<?xml version="1.0" encoding="UTF-8"?>
<!-- Generated by org.testng.reporters.JUnitReportReporter -->
<testsuite hostname="Hasan" name="learning.maven.MavenMarch12018.TestCaseOne" tests="2" failures="0" timestamp="2 Apr 2018 20:11:27 GMT" time="0.003" errors="2">
  <testcase name="funtionTwo" time="0.002" classname="learning.maven.MavenMarch12018.TestCaseOne">
    <error type="java.lang.NullPointerException">
      <![CDATA[java.lang.NullPointerException
	at learning.maven.MavenMarch12018.TestCaseOne.afterMethod(TestCaseOne.java:56)
	at sun.reflect.NativeMethodAccessorImpl.invoke0(Native Method)
	at sun.reflect.NativeMethodAccessorImpl.invoke(NativeMethodAccessorImpl.java:62)
	at sun.reflect.DelegatingMethodAccessorImpl.invoke(DelegatingMethodAccessorImpl.java:43)
	at java.lang.reflect.Method.invoke(Method.java:498)
	at org.testng.internal.MethodInvocationHelper.invokeMethod(MethodInvocationHelper.java:85)
	at org.testng.internal.Invoker.invokeConfigurationMethod(Invoker.java:510)
	at org.testng.internal.Invoker.invokeConfigurations(Invoker.java:211)
	at org.testng.internal.Invoker.invokeMethod(Invoker.java:703)
	at org.testng.internal.Invoker.invokeTestMethod(Invoker.java:816)
	at org.testng.internal.Invoker.invokeTestMethods(Invoker.java:1124)
	at org.testng.internal.TestMethodWorker.invokeTestMethods(TestMethodWorker.java:125)
	at org.testng.internal.TestMethodWorker.run(TestMethodWorker.java:108)
	at org.testng.TestRunner.privateRun(TestRunner.java:774)
	at org.testng.TestRunner.run(TestRunner.java:624)
	at org.testng.SuiteRunner.runTest(SuiteRunner.java:359)
	at org.testng.SuiteRunner.runSequentially(SuiteRunner.java:354)
	at org.testng.SuiteRunner.privateRun(SuiteRunner.java:312)
	at org.testng.SuiteRunner.run(SuiteRunner.java:261)
	at org.testng.SuiteRunnerWorker.runSuite(SuiteRunnerWorker.java:52)
	at org.testng.SuiteRunnerWorker.run(SuiteRunnerWorker.java:86)
	at org.testng.TestNG.runSuitesSequentially(TestNG.java:1215)
	at org.testng.TestNG.runSuitesLocally(TestNG.java:1140)
	at org.testng.TestNG.run(TestNG.java:1048)
	at org.apache.maven.surefire.testng.TestNGExecutor.run(TestNGExecutor.java:281)
	at org.apache.maven.surefire.testng.TestNGXmlTestSuite.execute(TestNGXmlTestSuite.java:75)
	at org.apache.maven.surefire.testng.TestNGProvider.invoke(TestNGProvider.java:121)
	at org.apache.maven.surefire.booter.ForkedBooter.invokeProviderInSameClassLoader(ForkedBooter.java:290)
	at org.apache.maven.surefire.booter.ForkedBooter.runSuitesInProcess(ForkedBooter.java:242)
	at org.apache.maven.surefire.booter.ForkedBooter.main(ForkedBooter.java:121)
]]>
    </error>
  </testcase> <!-- funtionTwo -->
  <testcase name="funtionThree" time="0.001" classname="learning.maven.MavenMarch12018.TestCaseOne">
    <error type="java.lang.Throwable" message="Method TestCaseOne.funtionThree()[pri:1, instance:learning.maven.MavenMarch12018.TestCaseOne@668bc3d5] depends on not successfully finished methods">
      <![CDATA[java.lang.Throwable: Method TestCaseOne.funtionThree()[pri:1, instance:learning.maven.MavenMarch12018.TestCaseOne@668bc3d5] depends on not successfully finished methods
	at org.testng.internal.Invoker.invokeTestMethods(Invoker.java:1033)
	at org.testng.internal.TestMethodWorker.invokeTestMethods(TestMethodWorker.java:125)
	at org.testng.internal.TestMethodWorker.run(TestMethodWorker.java:108)
	at org.testng.TestRunner.privateRun(TestRunner.java:774)
	at org.testng.TestRunner.run(TestRunner.java:624)
	at org.testng.SuiteRunner.runTest(SuiteRunner.java:359)
	at org.testng.SuiteRunner.runSequentially(SuiteRunner.java:354)
	at org.testng.SuiteRunner.privateRun(SuiteRunner.java:312)
	at org.testng.SuiteRunner.run(SuiteRunner.java:261)
	at org.testng.SuiteRunnerWorker.runSuite(SuiteRunnerWorker.java:52)
	at org.testng.SuiteRunnerWorker.run(SuiteRunnerWorker.java:86)
	at org.testng.TestNG.runSuitesSequentially(TestNG.java:1215)
	at org.testng.TestNG.runSuitesLocally(TestNG.java:1140)
	at org.testng.TestNG.run(TestNG.java:1048)
	at org.apache.maven.surefire.testng.TestNGExecutor.run(TestNGExecutor.java:281)
	at org.apache.maven.surefire.testng.TestNGXmlTestSuite.execute(TestNGXmlTestSuite.java:75)
	at org.apache.maven.surefire.testng.TestNGProvider.invoke(TestNGProvider.java:121)
	at org.apache.maven.surefire.booter.ForkedBooter.invokeProviderInSameClassLoader(ForkedBooter.java:290)
	at org.apache.maven.surefire.booter.ForkedBooter.runSuitesInProcess(ForkedBooter.java:242)
	at org.apache.maven.surefire.booter.ForkedBooter.main(ForkedBooter.java:121)
]]>
    </error>
  </testcase> <!-- funtionThree -->
</testsuite> <!-- learning.maven.MavenMarch12018.TestCaseOne -->
